<?xml version="1.0" encoding="utf-8"?>
<!-- This URDF was automatically created by SolidWorks to URDF Exporter! Originally created by Stephen Brawner (brawner@gmail.com) 
     Commit Version: 1.6.0-4-g7f85cfe  Build Version: 1.6.7995.38578
     For more information, please see http://wiki.ros.org/sw_urdf_exporter -->
<robot
  name="parallel_3rrr">
  <link
    name="base_link">
    <inertial>
      <origin
        xyz="1.2493E-17 4.1643E-17 -9.8988E-19"
        rpy="0 0 0" />
      <mass
        value="0.81361" />
      <inertia
        ixx="0.0063219"
        ixy="-2.5166E-18"
        ixz="1.0902E-18"
        iyy="0.0063219"
        iyz="-2.8025E-18"
        izz="0.01263" />
    </inertial>
    <visual>
      <origin
        xyz="0 0 0"
        rpy="0 0 0" />
      <geometry>
        <mesh
          filename="package://parallel_3rrr/meshes/base_link.STL" />
      </geometry>
      <material
        name="">
        <color
          rgba="0.79216 0.81961 0.93333 1" />
      </material>
    </visual>
    <collision>
      <origin
        xyz="0 0 0"
        rpy="0 0 0" />
      <geometry>
        <mesh
          filename="package://parallel_3rrr/meshes/base_link.STL" />
      </geometry>
    </collision>
  </link>
  <link
    name="link11">
    <inertial>
      <origin
        xyz="0.15 5.5511E-17 3.5127E-17"
        rpy="0 0 0" />
      <mass
        value="0.061571" />
      <inertia
        ixx="2.5818E-06"
        ixy="-7.6021E-20"
        ixz="1.0602E-21"
        iyy="0.00048992"
        iyz="-9.0446E-22"
        izz="0.00049148" />
    </inertial>
    <visual>
      <origin
        xyz="0 0 0"
        rpy="0 0 0" />
      <geometry>
        <mesh
          filename="package://parallel_3rrr/meshes/link11.STL" />
      </geometry>
      <material
        name="">
        <color
          rgba="0.79216 0.81961 0.93333 1" />
      </material>
    </visual>
    <collision>
      <origin
        xyz="0 0 0"
        rpy="0 0 0" />
      <geometry>
        <mesh
          filename="package://parallel_3rrr/meshes/link11.STL" />
      </geometry>
    </collision>
  </link>
  <joint
    name="joint11"
    type="continuous">
    <origin
      xyz="0 0.23094 0"
      rpy="0 0 0.46501" />
    <parent
      link="base_link" />
    <child
      link="link11" />
    <axis
      xyz="0 0 1" />
  </joint>
  <link
    name="link12">
    <inertial>
      <origin
        xyz="0.15 -2.2204E-16 1.3245E-16"
        rpy="0 0 0" />
      <mass
        value="0.061571" />
      <inertia
        ixx="2.5818E-06"
        ixy="-1.5141E-20"
        ixz="-3.2527E-21"
        iyy="0.00048992"
        iyz="-1.5123E-21"
        izz="0.00049148" />
    </inertial>
    <visual>
      <origin
        xyz="0 0 0"
        rpy="0 0 0" />
      <geometry>
        <mesh
          filename="package://parallel_3rrr/meshes/link12.STL" />
      </geometry>
      <material
        name="">
        <color
          rgba="0.79216 0.81961 0.93333 1" />
      </material>
    </visual>
    <collision>
      <origin
        xyz="0 0 0"
        rpy="0 0 0" />
      <geometry>
        <mesh
          filename="package://parallel_3rrr/meshes/link12.STL" />
      </geometry>
    </collision>
  </link>
  <joint
    name="joint12"
    type="continuous">
    <origin
      xyz="0.3 0 0"
      rpy="0 0 2.2116" />
    <parent
      link="link11" />
    <child
      link="link12" />
    <axis
      xyz="0 0 -1" />
  </joint>
  <link
    name="link21">
    <inertial>
      <origin
        xyz="0.15 -1.3878E-16 -7.3222E-17"
        rpy="0 0 0" />
      <mass
        value="0.061571" />
      <inertia
        ixx="2.5818E-06"
        ixy="-7.5704E-21"
        ixz="-1.9583E-21"
        iyy="0.00048992"
        iyz="1.9024E-22"
        izz="0.00049148" />
    </inertial>
    <visual>
      <origin
        xyz="0 0 0"
        rpy="0 0 0" />
      <geometry>
        <mesh
          filename="package://parallel_3rrr/meshes/link21.STL" />
      </geometry>
      <material
        name="">
        <color
          rgba="0.79216 0.81961 0.93333 1" />
      </material>
    </visual>
    <collision>
      <origin
        xyz="0 0 0"
        rpy="0 0 0" />
      <geometry>
        <mesh
          filename="package://parallel_3rrr/meshes/link21.STL" />
      </geometry>
    </collision>
  </link>
  <joint
    name="joint21"
    type="continuous">
    <origin
      xyz="0.2 -0.11547 0"
      rpy="0 0 -1.8453" />
    <parent
      link="base_link" />
    <child
      link="link21" />
    <axis
      xyz="0 0 1" />
  </joint>
  <link
    name="link22">
    <inertial>
      <origin
        xyz="0.15 4.4409E-16 -1.9916E-16"
        rpy="0 0 0" />
      <mass
        value="0.061571" />
      <inertia
        ixx="2.5818E-06"
        ixy="-1.9641E-20"
        ixz="-2.3829E-21"
        iyy="0.00048992"
        iyz="-4.7096E-23"
        izz="0.00049148" />
    </inertial>
    <visual>
      <origin
        xyz="0 0 0"
        rpy="0 0 0" />
      <geometry>
        <mesh
          filename="package://parallel_3rrr/meshes/link22.STL" />
      </geometry>
      <material
        name="">
        <color
          rgba="0.79216 0.81961 0.93333 1" />
      </material>
    </visual>
    <collision>
      <origin
        xyz="0 0 0"
        rpy="0 0 0" />
      <geometry>
        <mesh
          filename="package://parallel_3rrr/meshes/link22.STL" />
      </geometry>
    </collision>
  </link>
  <joint
    name="joint22"
    type="continuous">
    <origin
      xyz="0.3 0 0"
      rpy="0 0 2.2001" />
    <parent
      link="link21" />
    <child
      link="link22" />
    <axis
      xyz="0 0 1" />
  </joint>
  <link
    name="link31">
    <inertial>
      <origin
        xyz="0.15 -8.3267E-17 6.8576E-18"
        rpy="0 0 0" />
      <mass
        value="0.061571" />
      <inertia
        ixx="2.5818E-06"
        ixy="-2.7582E-20"
        ixz="1.6934E-23"
        iyy="0.00048992"
        iyz="8.022E-22"
        izz="0.00049148" />
    </inertial>
    <visual>
      <origin
        xyz="0 0 0"
        rpy="0 0 0" />
      <geometry>
        <mesh
          filename="package://parallel_3rrr/meshes/link31.STL" />
      </geometry>
      <material
        name="">
        <color
          rgba="0.79216 0.81961 0.93333 1" />
      </material>
    </visual>
    <collision>
      <origin
        xyz="0 0 0"
        rpy="0 0 0" />
      <geometry>
        <mesh
          filename="package://parallel_3rrr/meshes/link31.STL" />
      </geometry>
    </collision>
  </link>
  <joint
    name="joint31"
    type="continuous">
    <origin
      xyz="-0.2 -0.11547 0"
      rpy="0 0 2.7867" />
    <parent
      link="base_link" />
    <child
      link="link31" />
    <axis
      xyz="0 0 1" />
  </joint>
  <link
    name="link32">
    <inertial>
      <origin
        xyz="0.15 2.2204E-16 7.6979E-17"
        rpy="0 0 0" />
      <mass
        value="0.061571" />
      <inertia
        ixx="2.5818E-06"
        ixy="3.6475E-20"
        ixz="-1.5085E-21"
        iyy="0.00048992"
        iyz="-3.1167E-22"
        izz="0.00049148" />
    </inertial>
    <visual>
      <origin
        xyz="0 0 0"
        rpy="0 0 0" />
      <geometry>
        <mesh
          filename="package://parallel_3rrr/meshes/link32.STL" />
      </geometry>
      <material
        name="">
        <color
          rgba="0.79216 0.81961 0.93333 1" />
      </material>
    </visual>
    <collision>
      <origin
        xyz="0 0 0"
        rpy="0 0 0" />
      <geometry>
        <mesh
          filename="package://parallel_3rrr/meshes/link32.STL" />
      </geometry>
    </collision>
  </link>
  <joint
    name="joint32"
    type="continuous">
    <origin
      xyz="0.3 0 0"
      rpy="0 0 2.2001" />
    <parent
      link="link31" />
    <child
      link="link32" />
    <axis
      xyz="0 0 1" />
  </joint>
</robot>