<sdf version='1.6'>
<model name='parallel_3rrr'>
<link name='base_link'>
<pose>0.15000000-0.150000000.000000000.000000000.00000000-0.52359878</pose>
<inertial>
<pose>0 0 0 0 0 0</pose>
<mass>0.81361</mass>
<inertia>
<ixx>0.0063219</ixx>
<ixy>-2.5166e-18</ixy>
<ixz>1.0902e-18</ixz>
<iyy>0.0063219</iyy>
<iyz>-2.8025e-18</iyz>
<izz>0.01263</izz>
</inertia>
</inertial>
<collision name='base_link_collision'>
<pose>0 0 0 0 0 0</pose>
<geometry>
<mesh>
<scale>1 1 1</scale>
<uri>/home/jsitler/catkin_workspace/uuv_ws/src/uvms-perching/src/parallel_3rrr/meshes/base_link.STL</uri>
</mesh>
</geometry>
</collision>
<visual name='base_link_visual'>
<pose>0 0 0 0 0 0</pose>
<geometry>
<mesh>
<scale>1 1 1</scale>
<uri>/home/jsitler/catkin_workspace/uuv_ws/src/uvms-perching/src/parallel_3rrr/meshes/base_link.STL</uri>
</mesh>
</geometry>
</visual>
</link>
<link name='link11'>
<pose>0.26547005 -0.35000000 0.00000000 0.00000000 0.00000000 1.77768853 </pose>
<inertial>
<pose>0.15 0 0 0 0 0</pose>
<mass>0.061571</mass>
<inertia>
<ixx>2.5818e-06</ixx>
<ixy>-7.6021e-20</ixy>
<ixz>1.0602e-21</ixz>
<iyy>0.00048992</iyy>
<iyz>-9.0446e-22</iyz>
<izz>0.00049148</izz>
</inertia>
</inertial>
<collision name='link11_collision'>
<pose>0 0 0 0 0 0</pose>
<geometry>
<mesh>
<scale>1 1 1</scale>
<uri>/home/jsitler/catkin_workspace/uuv_ws/src/uvms-perching/src/parallel_3rrr/meshes/link11.STL</uri>
</mesh>
</geometry>
</collision>
<visual name='link11_visual'>
<pose>0 0 0 0 0 0</pose>
<geometry>
<mesh>
<scale>1 1 1</scale>
<uri>/home/jsitler/catkin_workspace/uuv_ws/src/uvms-perching/src/parallel_3rrr/meshes/link11.STL</uri>
</mesh>
</geometry>
</visual>
</link>
<joint name='joint11' type='revolute'>
<child>link11</child>
<parent>base_link</parent>
<axis>
<xyz>0 0 1</xyz>
<limit>
<lower>-1e+16</lower>
<upper>1e+16</upper>
</limit>
<dynamics>
<damping>0.05</damping>
<friction>0</friction>
<spring_reference>0</spring_reference>
<spring_stiffness>0</spring_stiffness>
</dynamics>
</axis>
</joint>
<link name='link12'>
<pose>0.20384424 -0.05639779 0.00000000 0.00000000 0.00000000 -0.70146921 </pose>
<inertial>
<pose>0.15 0 0 0 0 0</pose>
<mass>0.061571</mass>
<inertia>
<ixx>2.5818e-06</ixx>
<ixy>-1.5141e-20</ixy>
<ixz>-3.2527e-21</ixz>
<iyy>0.00048992</iyy>
<iyz>-1.5123e-21</iyz>
<izz>0.00049148</izz>
</inertia>
</inertial>
<collision name='link12_collision'>
<pose>0 0 0 0 0 0</pose>
<geometry>
<mesh>
<scale>1 1 1</scale>
<uri>/home/jsitler/catkin_workspace/uuv_ws/src/uvms-perching/src/parallel_3rrr/meshes/link12.STL</uri>
</mesh>
</geometry>
</collision>
<visual name='link12_visual'>
<pose>0 0 0 0 0 0</pose>
<geometry>
<mesh>
<scale>1 1 1</scale>
<uri>/home/jsitler/catkin_workspace/uuv_ws/src/uvms-perching/src/parallel_3rrr/meshes/link12.STL</uri>
</mesh>
</geometry>
</visual>
</link>
<joint name='joint12' type='revolute'>
<child>link12</child>
<parent>link11</parent>
<axis>
<xyz>0 0 -1</xyz>
<limit>
<lower>-1e+16</lower>
<upper>1e+16</upper>
</limit>
<dynamics>
<damping>0.05</damping>
<friction>0</friction>
<spring_reference>0</spring_reference>
<spring_stiffness>0</spring_stiffness>
</dynamics>
</axis>
</joint>
<link name='link21'>
<pose>0.26547000 0.05000000 0.00000000 0.00000000 0.00000000 2.61780000 </pose>
<inertial>
<pose>0.15 0 0 0 0 0</pose>
<mass>0.061571</mass>
<inertia>
<ixx>2.5818e-06</ixx>
<ixy>-7.5704e-21</ixy>
<ixz>-1.9583e-21</ixz>
<iyy>0.00048992</iyy>
<iyz>1.9024e-22</iyz>
<izz>0.00049148</izz>
</inertia>
</inertial>
<collision name='link21_collision'>
<pose>0 0 0 0 0 0</pose>
<geometry>
<mesh>
<scale>1 1 1</scale>
<uri>/home/jsitler/catkin_workspace/uuv_ws/src/uvms-perching/src/parallel_3rrr/meshes/link21.STL</uri>
</mesh>
</geometry>
</collision>
<visual name='link21_visual'>
<pose>0 0 0 0 0 0</pose>
<geometry>
<mesh>
<scale>1 1 1</scale>
<uri>/home/jsitler/catkin_workspace/uuv_ws/src/uvms-perching/src/parallel_3rrr/meshes/link21.STL</uri>
</mesh>
</geometry>
</visual>
</link>
<joint name='joint21' type='revolute'>
<child>link21</child>
<parent>base_link</parent>
<axis>
<xyz>0 0 1</xyz>
<limit>
<lower>-1e+16</lower>
<upper>1e+16</upper>
</limit>
<dynamics>
<damping>0.05</damping>
<friction>0</friction>
<spring_reference>0</spring_reference>
<spring_stiffness>0</spring_stiffness>
</dynamics>
</axis>
</joint>
<link name='link22'>
<pose>0.00569360 0.20005000 0.00000000 0.00000000 0.00000000 1.58980000 </pose>
<inertial>
<pose>0.15 0 0 0 0 0</pose>
<mass>0.061571</mass>
<inertia>
<ixx>2.5818e-06</ixx>
<ixy>-1.9641e-20</ixy>
<ixz>-2.3829e-21</ixz>
<iyy>0.00048992</iyy>
<iyz>-4.7096e-23</iyz>
<izz>0.00049148</izz>
</inertia>
</inertial>
<collision name='link22_collision'>
<pose>0 0 0 0 0 0</pose>
<geometry>
<mesh>
<scale>1 1 1</scale>
<uri>/home/jsitler/catkin_workspace/uuv_ws/src/uvms-perching/src/parallel_3rrr/meshes/link22.STL</uri>
</mesh>
</geometry>
</collision>
<visual name='link22_visual'>
<pose>0 0 0 0 0 0</pose>
<geometry>
<mesh>
<scale>1 1 1</scale>
<uri>/home/jsitler/catkin_workspace/uuv_ws/src/uvms-perching/src/parallel_3rrr/meshes/link22.STL</uri>
</mesh>
</geometry>
</visual>
</link>
<joint name='joint22' type='revolute'>
<child>link22</child>
<parent>link21</parent>
<axis>
<xyz>0 0 1</xyz>
<limit>
<lower>-1e+16</lower>
<upper>1e+16</upper>
</limit>
<dynamics>
<damping>0.05</damping>
<friction>0</friction>
<spring_reference>0</spring_reference>
<spring_stiffness>0</spring_stiffness>
</dynamics>
</axis>
</joint>
<link name='link31'>
<pose>-0.08094000 -0.15000000 0.00000000 0.00000000 0.00000000 -1.95010000 </pose>
<inertial>
<pose>0.15 0 0 0 0 0</pose>
<mass>0.061571</mass>
<inertia>
<ixx>2.5818e-06</ixx>
<ixy>-2.7582e-20</ixy>
<ixz>1.6934e-23</ixz>
<iyy>0.00048992</iyy>
<iyz>8.022e-22</iyz>
<izz>0.00049148</izz>
</inertia>
</inertial>
<collision name='link31_collision'>
<pose>0 0 0 0 0 0</pose>
<geometry>
<mesh>
<scale>1 1 1</scale>
<uri>/home/jsitler/catkin_workspace/uuv_ws/src/uvms-perching/src/parallel_3rrr/meshes/link31.STL</uri>
</mesh>
</geometry>
</collision>
<visual name='link31_visual'>
<pose>0 0 0 0 0 0</pose>
<geometry>
<mesh>
<scale>1 1 1</scale>
<uri>/home/jsitler/catkin_workspace/uuv_ws/src/uvms-perching/src/parallel_3rrr/meshes/link31.STL</uri>
</mesh>
</geometry>
</visual>
</link>
<joint name='joint31' type='revolute'>
<child>link31</child>
<parent>base_link</parent>
<axis>
<xyz>0 0 1</xyz>
<limit>
<lower>-1e+16</lower>
<upper>1e+16</upper>
</limit>
<dynamics>
<damping>0.05</damping>
<friction>0</friction>
<spring_reference>0</spring_reference>
<spring_stiffness>0</spring_stiffness>
</dynamics>
</axis>
</joint>
<link name='link32'>
<pose>-0.19203000 -0.42868000 0.00000000 0.00000000 0.00000000 2.50360000 </pose>
<inertial>
<pose>0.15 0 0 0 0 0</pose>
<mass>0.061571</mass>
<inertia>
<ixx>2.5818e-06</ixx>
<ixy>3.6475e-20</ixy>
<ixz>-1.5085e-21</ixz>
<iyy>0.00048992</iyy>
<iyz>-3.1167e-22</iyz>
<izz>0.00049148</izz>
</inertia>
</inertial>
<collision name='link32_collision'>
<pose>0 0 0 0 0 0</pose>
<geometry>
<mesh>
<scale>1 1 1</scale>
<uri>/home/jsitler/catkin_workspace/uuv_ws/src/uvms-perching/src/parallel_3rrr/meshes/link32.STL</uri>
</mesh>
</geometry>
</collision>
<visual name='link32_visual'>
<pose>0 0 0 0 0 0</pose>
<geometry>
<mesh>
<scale>1 1 1</scale>
<uri>/home/jsitler/catkin_workspace/uuv_ws/src/uvms-perching/src/parallel_3rrr/meshes/link32.STL</uri>
</mesh>
</geometry>
</visual>
</link>
<joint name='joint32' type='revolute'>
<child>link32</child>
<parent>link31</parent>
<axis>
<xyz>0 0 1</xyz>
<limit>
<lower>-1e+16</lower>
<upper>1e+16</upper>
</limit>
<dynamics>
<damping>0.05</damping>
<friction>0</friction>
<spring_reference>0</spring_reference>
<spring_stiffness>0</spring_stiffness>
</dynamics>
</axis>
</joint>
<joint name='arm1base' type='revolute'>
<child>link12</child>
<parent>world</parent>
<pose> 0.3 0 0 0 0 0</pose>  
<axis>
<xyz>0 0 1</xyz>
<limit>
<lower>-1e+16</lower>
<upper>1e+16</upper>
</limit>
<dynamics>
<damping>0.05</damping>
<friction>0</friction>
<spring_reference>0</spring_reference>
<spring_stiffness>10</spring_stiffness>
</dynamics>
</axis>
</joint>
<joint name='arm2base' type='revolute'>
<child>link22</child>
<parent>world</parent>
<pose> 0.3 0 0 0 0 0</pose>  
<axis>
<xyz>0 0 1</xyz>
<limit>
<lower>-1e+16</lower>
<upper>1e+16</upper>
</limit>
<dynamics>
<damping>0.05</damping>
<friction>0</friction>
<spring_reference>0</spring_reference>
<spring_stiffness>10</spring_stiffness>
</dynamics> 
</axis>
</joint>
<joint name='arm3base' type='revolute'>
<child>link32</child>
<parent>world</parent>
<pose> 0.3 0 0 0 0 0</pose>  
<axis>
<xyz>0 0 1</xyz>
<limit>
<lower>-1e+16</lower>
<upper>1e+16</upper>
</limit>
<dynamics>
<damping>0.05</damping>
<friction>0</friction>
<spring_reference>0</spring_reference>
<spring_stiffness>10</spring_stiffness>
</dynamics>
</axis>
</joint>
</model>
</sdf>
