<?xml version="1.0" ?>
<sdf version="1.5">
<model name="four_bar_sdf">
<pose>0 0 0 0 0 0</pose>
<self_collide>true</self_collide>
<link name="linkROV">
<pose>-0.2286 0 0 0 0 0</pose>
<inertial>
<mass>1.0</mass>
<inertia>
<ixx>0.0227</ixx>
<iyy>0.0306</iyy>
<izz>0.0269</izz>
<ixy>0.0</ixy>
<ixz>0.0</ixz>
<iyz>0.0</iyz>
</inertia>
</inertial>
<collision name="linkROV_collision">
<geometry>
<box>
<size>0.4572 0.33805 0.39785</size>
</box>
</geometry>
</collision>
<visual name="linkROV_visual">
<geometry>
<box>
<size>0.4572 0.33805 0.39785</size>
</box>
</geometry>
<material>
<color rgba="0.3 0.3 0.3 1.0"/>
</material>
</visual>
</link>
<link name="arm1link1">
<pose>0.05750000 0.10000000 -0.10000000 -0.53999705 -0.00000000 0.00000000 </pose>
<inertial>
<mass>0.575</mass>
<inertia>
<ixx>3.8333e-05</ixx>
<iyy>6.5286e-04</iyy>
<izz>6.5286e-04</izz>
<ixy>0.0</ixy>
<ixz>0.0</ixz>
<iyz>0.0</iyz>
</inertia>
</inertial>
<collision name="arm1link1_collision">
<geometry>
<box>
<size>0.115 0.02 0.02</size>
</box>
</geometry>
</collision>
<visual name="arm1link1_visual">
<geometry>
<box>
<size>0.115 0.02 0.02</size>
</box>
</geometry>
<material>
<color rgba="0.3 0.3 0.3 1.0"/>
</material>
</visual>
</link>
<link name="arm1link2">
<pose>0.17353082 0.13293141 -0.11973993 -0.46461711 0.28587709 0.51249106 </pose>
<inertial>
<mass>0.700</mass>
<inertia>
<ixx>4.6667e-05</ixx>
<iyy>1.1667e-03</iyy>
<izz>1.1667e-03</izz>
<ixy>0.0</ixy>
<ixz>0.0</ixz>
<iyz>0.0</iyz>
</inertia>
</inertial>
<collision name="arm1link2_collision">
<geometry>
<box>
<size>0.140 0.02 0.02</size>
</box>
</geometry>
</collision>
<visual name="arm1link2_visual">
<geometry>
<box>
<size>0.140 0.02 0.02</size>
</box>
</geometry>
<material>
<color rgba="0.3 0.3 0.3 1.0"/>
</material>
</visual>
</link>
<link name="arm1link3">
<pose>0.23308412 0.21517337 -0.16903787 -0.01065870 0.53990227 1.55006384 </pose>
<inertial>
<mass>0.575</mass>
<inertia>
<ixx>3.8333e-05</ixx>
<iyy>6.5286e-04</iyy>
<izz>6.5286e-04</izz>
<ixy>0.0</ixy>
<ixz>0.0</ixz>
<iyz>0.0</iyz>
</inertia>
</inertial>
<collision name="arm1link3_collision">
<geometry>
<box>
<size>0.115 0.02 0.02</size>
</box>
</geometry>
</collision>
<visual name="arm1link3_visual">
<geometry>
<box>
<size>0.115 0.02 0.02</size>
</box>
</geometry>
<material>
<color rgba="0.3 0.3 0.3 1.0"/>
</material>
</visual>
</link>
<link name="arm1link4">
<pose>0.23499570 0.30736264 -0.22429847 -0.01028446 0.53990227 1.55006384 </pose>
<inertial>
<mass>0.500</mass>
<inertia>
<ixx>3.3333e-05</ixx>
<iyy>4.3333e-04</iyy>
<izz>4.3333e-04</izz>
<ixy>0.0</ixy>
<ixz>0.0</ixz>
<iyz>0.0</iyz>
</inertia>
</inertial>
<collision name="arm1link4_collision">
<geometry>
<box>
<size>0.100 0.02 0.02</size>
</box>
</geometry>
</collision>
<visual name="arm1link4_visual">
<geometry>
<box>
<size>0.100 0.02 0.02</size>
</box>
</geometry>
<material>
<color rgba="0.3 0.3 0.3 1.0"/>
</material>
</visual>
</link>
<link name="arm1link5">
<pose>0.29338480 0.35025603 -0.25003496 -0.53999022 0.00058913 0.00025504 </pose>
<inertial>
<mass>0.575</mass>
<inertia>
<ixx>3.8333e-05</ixx>
<iyy>6.5286e-04</iyy>
<izz>6.5286e-04</izz>
<ixy>0.0</ixy>
<ixz>0.0</ixz>
<iyz>0.0</iyz>
</inertia>
</inertial>
<collision name="arm1link5_collision">
<geometry>
<box>
<size>0.115 0.02 0.02</size>
</box>
</geometry>
</collision>
<visual name="arm1link5_visual">
<geometry>
<box>
<size>0.115 0.02 0.02</size>
</box>
</geometry>
<material>
<color rgba="0.3 0.3 0.3 1.0"/>
</material>
</visual>
</link>
<link name="arm1link6">
<pose>0.41088478 0.35028600 -0.25010418 -0.00025477 0.00058913 0.00025504 </pose>
<inertial>
<mass>0.600</mass>
<inertia>
<ixx>4.0000e-05</ixx>
<iyy>7.4000e-04</iyy>
<izz>7.4000e-04</izz>
<ixy>0.0</ixy>
<ixz>0.0</ixz>
<iyz>0.0</iyz>
</inertia>
</inertial>
<collision name="arm1link6_collision">
<geometry>
<box>
<size>0.120 0.02 0.02</size>
</box>
</geometry>
</collision>
<visual name="arm1link6_visual">
<geometry>
<box>
<size>0.120 0.02 0.02</size>
</box>
</geometry>
<material>
<color rgba="0.3 0.3 0.3 1.0"/>
</material>
</visual>
</link>
<link name="arm2link1">
<pose>0.05750000 -0.10000000 -0.10000000 -2.35580000 0.00000000 0.00000000 </pose>
<inertial>
<mass>0.575</mass>
<inertia>
<ixx>3.8333e-05</ixx>
<iyy>6.5286e-04</iyy>
<izz>6.5286e-04</izz>
<ixy>0.0</ixy>
<ixz>0.0</ixz>
<iyz>0.0</iyz>
</inertia>
</inertial>
<collision name="arm2link1_collision">
<geometry>
<box>
<size>0.115 0.02 0.02</size>
</box>
</geometry>
</collision>
<visual name="arm2link1_visual">
<geometry>
<box>
<size>0.115 0.02 0.02</size>
</box>
</geometry>
<material>
<color rgba="0.3 0.3 0.3 1.0"/>
</material>
</visual>
</link>
<link name="arm2link2">
<pose>0.18499000 -0.09920200 -0.09920100 -2.35580000 -0.01141600 0.01140700 </pose>
<inertial>
<mass>0.700</mass>
<inertia>
<ixx>4.6667e-05</ixx>
<iyy>1.1667e-03</iyy>
<izz>1.1667e-03</izz>
<ixy>0.0</ixy>
<ixz>0.0</ixz>
<iyz>0.0</iyz>
</inertia>
</inertial>
<collision name="arm2link2_collision">
<geometry>
<box>
<size>0.140 0.02 0.02</size>
</box>
</geometry>
</collision>
<visual name="arm2link2_visual">
<geometry>
<box>
<size>0.140 0.02 0.02</size>
</box>
</geometry>
<material>
<color rgba="0.3 0.3 0.3 1.0"/>
</material>
</visual>
</link>
<link name="arm2link3">
<pose>0.25026000 -0.13891000 -0.13894000 3.05960000 0.78246000 -1.68690000 </pose>
<inertial>
<mass>0.575</mass>
<inertia>
<ixx>3.8333e-05</ixx>
<iyy>6.5286e-04</iyy>
<izz>6.5286e-04</izz>
<ixy>0.0</ixy>
<ixz>0.0</ixz>
<iyz>0.0</iyz>
</inertia>
</inertial>
<collision name="arm2link3_collision">
<geometry>
<box>
<size>0.115 0.02 0.02</size>
</box>
</geometry>
</collision>
<visual name="arm2link3_visual">
<geometry>
<box>
<size>0.115 0.02 0.02</size>
</box>
</geometry>
<material>
<color rgba="0.3 0.3 0.3 1.0"/>
</material>
</visual>
</link>
<link name="arm2link4">
<pose>0.24143000 -0.21463000 -0.21473000 3.05930000 0.78246000 -1.68690000 </pose>
<inertial>
<mass>0.500</mass>
<inertia>
<ixx>3.3333e-05</ixx>
<iyy>4.3333e-04</iyy>
<izz>4.3333e-04</izz>
<ixy>0.0</ixy>
<ixz>0.0</ixz>
<iyz>0.0</iyz>
</inertia>
</inertial>
<collision name="arm2link4_collision">
<geometry>
<box>
<size>0.100 0.02 0.02</size>
</box>
</geometry>
</collision>
<visual name="arm2link4_visual">
<geometry>
<box>
<size>0.100 0.02 0.02</size>
</box>
</geometry>
<material>
<color rgba="0.3 0.3 0.3 1.0"/>
</material>
</visual>
</link>
<link name="arm2link5">
<pose>0.29482000 -0.24982000 -0.24997000 -2.35570000 -0.00015365 0.00050454 </pose>
<inertial>
<mass>0.575</mass>
<inertia>
<ixx>3.8333e-05</ixx>
<iyy>6.5286e-04</iyy>
<izz>6.5286e-04</izz>
<ixy>0.0</ixy>
<ixz>0.0</ixz>
<iyz>0.0</iyz>
</inertia>
</inertial>
<collision name="arm2link5_collision">
<geometry>
<box>
<size>0.115 0.02 0.02</size>
</box>
</geometry>
</collision>
<visual name="arm2link5_visual">
<geometry>
<box>
<size>0.115 0.02 0.02</size>
</box>
</geometry>
<material>
<color rgba="0.3 0.3 0.3 1.0"/>
</material>
</visual>
</link>
<link name="arm2link6">
<pose>0.41232000 -0.24976000 -0.24996000 0.00047988 -0.00015365 0.00050454 </pose>
<inertial>
<mass>0.600</mass>
<inertia>
<ixx>4.0000e-05</ixx>
<iyy>7.4000e-04</iyy>
<izz>7.4000e-04</izz>
<ixy>0.0</ixy>
<ixz>0.0</ixz>
<iyz>0.0</iyz>
</inertia>
</inertial>
<collision name="arm2link6_collision">
<geometry>
<box>
<size>0.120 0.02 0.02</size>
</box>
</geometry>
</collision>
<visual name="arm2link6_visual">
<geometry>
<box>
<size>0.120 0.02 0.02</size>
</box>
</geometry>
<material>
<color rgba="0.3 0.3 0.3 1.0"/>
</material>
</visual>
</link>
<link name="arm3link1">
<pose>0.05750000 0.00000000 0.14142000 1.13830000 0.00000000 0.00000000 </pose>
<inertial>
<mass>0.575</mass>
<inertia>
<ixx>3.8333e-05</ixx>
<iyy>6.5286e-04</iyy>
<izz>6.5286e-04</izz>
<ixy>0.0</ixy>
<ixz>0.0</ixz>
<iyz>0.0</iyz>
</inertia>
</inertial>
<collision name="arm3link1_collision">
<geometry>
<box>
<size>0.115 0.02 0.02</size>
</box>
</geometry>
</collision>
<visual name="arm3link1_visual">
<geometry>
<box>
<size>0.115 0.02 0.02</size>
</box>
</geometry>
<material>
<color rgba="0.3 0.3 0.3 1.0"/>
</material>
</visual>
</link>
<link name="arm3link2">
<pose>0.16646000 -0.01988900 0.09834100 1.01010000 0.66293000 -0.36879000 </pose>
<inertial>
<mass>0.700</mass>
<inertia>
<ixx>4.6667e-05</ixx>
<iyy>1.1667e-03</iyy>
<izz>1.1667e-03</izz>
<ixy>0.0</ixy>
<ixz>0.0</ixz>
<iyz>0.0</iyz>
</inertia>
</inertial>
<collision name="arm3link2_collision">
<geometry>
<box>
<size>0.140 0.02 0.02</size>
</box>
</geometry>
</collision>
<visual name="arm3link2_visual">
<geometry>
<box>
<size>0.140 0.02 0.02</size>
</box>
</geometry>
<material>
<color rgba="0.3 0.3 0.3 1.0"/>
</material>
</visual>
</link>
<link name="arm3link3">
<pose>0.22294000 -0.01576800 0.10727000 0.18643000 -1.13010000 1.36520000 </pose>
<inertial>
<mass>0.575</mass>
<inertia>
<ixx>3.8333e-05</ixx>
<iyy>6.5286e-04</iyy>
<izz>6.5286e-04</izz>
<ixy>0.0</ixy>
<ixz>0.0</ixz>
<iyz>0.0</iyz>
</inertia>
</inertial>
<collision name="arm3link3_collision">
<geometry>
<box>
<size>0.115 0.02 0.02</size>
</box>
</geometry>
</collision>
<visual name="arm3link3_visual">
<geometry>
<box>
<size>0.115 0.02 0.02</size>
</box>
</geometry>
<material>
<color rgba="0.3 0.3 0.3 1.0"/>
</material>
</visual>
</link>
<link name="arm3link4">
<pose>0.23230000 0.02912100 0.20450000 0.18642000 -1.13010000 1.36520000 </pose>
<inertial>
<mass>0.500</mass>
<inertia>
<ixx>3.3333e-05</ixx>
<iyy>4.3333e-04</iyy>
<izz>4.3333e-04</izz>
<ixy>0.0</ixy>
<ixz>0.0</ixz>
<iyz>0.0</iyz>
</inertia>
</inertial>
<collision name="arm3link4_collision">
<geometry>
<box>
<size>0.100 0.02 0.02</size>
</box>
</geometry>
</collision>
<visual name="arm3link4_visual">
<geometry>
<box>
<size>0.100 0.02 0.02</size>
</box>
</geometry>
<material>
<color rgba="0.3 0.3 0.3 1.0"/>
</material>
</visual>
</link>
<link name="arm3link5">
<pose>0.29415000 0.04999800 0.24972000 1.13830000 0.00004484 -0.00002839 </pose>
<inertial>
<mass>0.575</mass>
<inertia>
<ixx>3.8333e-05</ixx>
<iyy>6.5286e-04</iyy>
<izz>6.5286e-04</izz>
<ixy>0.0</ixy>
<ixz>0.0</ixz>
<iyz>0.0</iyz>
</inertia>
</inertial>
<collision name="arm3link5_collision">
<geometry>
<box>
<size>0.115 0.02 0.02</size>
</box>
</geometry>
</collision>
<visual name="arm3link5_visual">
<geometry>
<box>
<size>0.115 0.02 0.02</size>
</box>
</geometry>
<material>
<color rgba="0.3 0.3 0.3 1.0"/>
</material>
</visual>
</link>
<link name="arm3link6">
<pose>0.41165000 0.04999500 0.24971000 -0.00002760 0.00004484 -0.00002839 </pose>
<inertial>
<mass>0.600</mass>
<inertia>
<ixx>4.0000e-05</ixx>
<iyy>7.4000e-04</iyy>
<izz>7.4000e-04</izz>
<ixy>0.0</ixy>
<ixz>0.0</ixz>
<iyz>0.0</iyz>
</inertia>
</inertial>
<collision name="arm3link6_collision">
<geometry>
<box>
<size>0.120 0.02 0.02</size>
</box>
</geometry>
</collision>
<visual name="arm3link6_visual">
<geometry>
<box>
<size>0.120 0.02 0.02</size>
</box>
</geometry>
<material>
<color rgba="0.3 0.3 0.3 1.0"/>
</material>
</visual>
</link>
<joint name="arm1_jointgrip" type="fixed">
<pose>0 0 0 0 0 0</pose>
<parent>world</parent>
<child>arm1link6</child>
</joint>
<joint name="arm1_joint1" type="revolute">
<pose>0 0 0 0 0 0</pose>
<parent>linkROV</parent>
<child>arm1link1</child>
<axis>
<xyz>1 0 0</xyz>
<dynamics>
<damping>0.05</damping>
<friction>0</friction>
<spring_reference>0</spring_reference>
<spring_stiffness>10.0</spring_stiffness>
</dynamics>
</axis>
</joint>
<joint name="arm1_joint2" type="revolute">
<pose>-0.07 0 0 0 0 0</pose>
<parent>arm1link1</parent>
<child>arm1link2</child>
<axis>
<xyz>0 0 1</xyz>
<dynamics>
<damping>0.05</damping>
<friction>0</friction>
<spring_reference>0</spring_reference>
<spring_stiffness>10.0</spring_stiffness>
</dynamics>
</axis>
</joint>
<joint name="arm1_joint3" type="revolute">
<pose>-0.0575 0 0 0 0 0</pose>
<parent>arm1link2</parent>
<child>arm1link3</child>
<axis>
<xyz>0 0 1</xyz>
<dynamics>
<damping>0.05</damping>
<friction>0</friction>
<spring_reference>0</spring_reference>
<spring_stiffness>10.0</spring_stiffness>
</dynamics>
</axis>
</joint>
<joint name="arm1_joint4" type="revolute">
<pose>-0.05 0 0 0 0 0</pose>
<parent>arm1link3</parent>
<child>arm1link4</child>
<axis>
<xyz>1 0 0</xyz>
<dynamics>
<damping>0.05</damping>
<friction>0</friction>
<spring_reference>0</spring_reference>
<spring_stiffness>10.0</spring_stiffness>
</dynamics>
</axis>
</joint>
<joint name="arm1_joint5" type="revolute">
<pose>-0.0575 0 0 0 0 0</pose>
<parent>arm1link4</parent>
<child>arm1link5</child>
<axis>
<xyz>0 0 1</xyz>
<dynamics>
<damping>0.05</damping>
<friction>0</friction>
<spring_reference>0</spring_reference>
<spring_stiffness>10.0</spring_stiffness>
</dynamics>
</axis>
</joint>
<joint name="arm1_joint6" type="revolute">
<pose>-0.06 0 0 0 0 0</pose>
<parent>arm1link5</parent>
<child>arm1link6</child>
<axis>
<xyz>1 0 0</xyz>
<dynamics>
<damping>0.05</damping>
<friction>0</friction>
<spring_reference>0</spring_reference>
<spring_stiffness>10.0</spring_stiffness>
</dynamics>
</axis>
</joint>
<joint name="arm2_jointgrip" type="fixed">
<pose>0 0 0 0 0 0</pose>
<parent>world</parent>
<child>arm2link6</child>
</joint>
<joint name="arm2_joint1" type="revolute">
<pose>0 0 0 0 0 0</pose>
<parent>linkROV</parent>
<child>arm2link1</child>
<axis>
<xyz>1 0 0</xyz>
<dynamics>
<damping>0.05</damping>
<friction>0</friction>
<spring_reference>0</spring_reference>
<spring_stiffness>10.0</spring_stiffness>
</dynamics>
</axis>
</joint>
<joint name="arm2_joint2" type="revolute">
<pose>-0.07 0 0 0 0 0</pose>
<parent>arm2link1</parent>
<child>arm2link2</child>
<axis>
<xyz>0 0 1</xyz>
<dynamics>
<damping>0.05</damping>
<friction>0</friction>
<spring_reference>0</spring_reference>
<spring_stiffness>10.0</spring_stiffness>
</dynamics>
</axis>
</joint>
<joint name="arm2_joint3" type="revolute">
<pose>-0.0575 0 0 0 0 0</pose>
<parent>arm2link2</parent>
<child>arm2link3</child>
<axis>
<xyz>0 0 1</xyz>
<dynamics>
<damping>0.05</damping>
<friction>0</friction>
<spring_reference>0</spring_reference>
<spring_stiffness>10.0</spring_stiffness>
</dynamics>
</axis>
</joint>
<joint name="arm2_joint4" type="revolute">
<pose>-0.05 0 0 0 0 0</pose>
<parent>arm2link3</parent>
<child>arm2link4</child>
<axis>
<xyz>1 0 0</xyz>
<dynamics>
<damping>0.05</damping>
<friction>0</friction>
<spring_reference>0</spring_reference>
<spring_stiffness>10.0</spring_stiffness>
</dynamics>
</axis>
</joint>
<joint name="arm2_joint5" type="revolute">
<pose>-0.0575 0 0 0 0 0</pose>
<parent>arm2link4</parent>
<child>arm2link5</child>
<axis>
<xyz>0 0 1</xyz>
<dynamics>
<damping>0.05</damping>
<friction>0</friction>
<spring_reference>0</spring_reference>
<spring_stiffness>10.0</spring_stiffness>
</dynamics>
</axis>
</joint>
<joint name="arm2_joint6" type="revolute">
<pose>-0.06 0 0 0 0 0</pose>
<parent>arm2link5</parent>
<child>arm2link6</child>
<axis>
<xyz>1 0 0</xyz>
<dynamics>
<damping>0.05</damping>
<friction>0</friction>
<spring_reference>0</spring_reference>
<spring_stiffness>10.0</spring_stiffness>
</dynamics>
</axis>
</joint>
<joint name="arm3_jointgrip" type="fixed">
<pose>0 0 0 0 0 0</pose>
<parent>world</parent>
<child>arm3link6</child>
</joint>
<joint name="arm3_joint1" type="revolute">
<pose>0 0 0 0 0 0</pose>
<parent>linkROV</parent>
<child>arm3link1</child>
<axis>
<xyz>1 0 0</xyz>
<dynamics>
<damping>0.05</damping>
<friction>0</friction>
<spring_reference>0</spring_reference>
<spring_stiffness>10.0</spring_stiffness>
</dynamics>
</axis>
</joint>
<joint name="arm3_joint2" type="revolute">
<pose>-0.07 0 0 0 0 0</pose>
<parent>arm3link1</parent>
<child>arm3link2</child>
<axis>
<xyz>0 0 1</xyz>
<dynamics>
<damping>0.05</damping>
<friction>0</friction>
<spring_reference>0</spring_reference>
<spring_stiffness>10.0</spring_stiffness>
</dynamics>
</axis>
</joint>
<joint name="arm3_joint3" type="revolute">
<pose>-0.0575 0 0 0 0 0</pose>
<parent>arm3link2</parent>
<child>arm3link3</child>
<axis>
<xyz>0 0 1</xyz>
<dynamics>
<damping>0.05</damping>
<friction>0</friction>
<spring_reference>0</spring_reference>
<spring_stiffness>10.0</spring_stiffness>
</dynamics>
</axis>
</joint>
<joint name="arm3_joint4" type="revolute">
<pose>-0.05 0 0 0 0 0</pose>
<parent>arm3link3</parent>
<child>arm3link4</child>
<axis>
<xyz>1 0 0</xyz>
<dynamics>
<damping>0.05</damping>
<friction>0</friction>
<spring_reference>0</spring_reference>
<spring_stiffness>10.0</spring_stiffness>
</dynamics>
</axis>
</joint>
<joint name="arm3_joint5" type="revolute">
<pose>-0.0575 0 0 0 0 0</pose>
<parent>arm3link4</parent>
<child>arm3link5</child>
<axis>
<xyz>0 0 1</xyz>
<dynamics>
<damping>0.05</damping>
<friction>0</friction>
<spring_reference>0</spring_reference>
<spring_stiffness>10.0</spring_stiffness>
</dynamics>
</axis>
</joint>
<joint name="arm3_joint6" type="revolute">
<pose>-0.06 0 0 0 0 0</pose>
<parent>arm3link5</parent>
<child>arm3link6</child>
<axis>
<xyz>1 0 0</xyz>
<dynamics>
<damping>0.05</damping>
<friction>0</friction>
<spring_reference>0</spring_reference>
<spring_stiffness>10.0</spring_stiffness>
</dynamics>
</axis>
</joint>
</model>
</sdf>
