<?xml version="1.0" ?>
<sdf version="1.5">
<model name="four_bar_sdf">
<pose>0 0 0 0 0 0</pose>
<self_collide>true</self_collide>
<link name="linkROV">
<pose>-0.2286 0 0 0 0 0</pose>
<inertial>
<mass>1.0</mass>
<inertia>
<ixx>0.0227</ixx>
<iyy>0.0306</iyy>
<izz>0.0269</izz>
<ixy>0.0</ixy>
<ixz>0.0</ixz>
<iyz>0.0</iyz>
</inertia>
</inertial>
<collision name="linkROV_collision">
<geometry>
<box>
<size>0.4572 0.33805 0.39785</size>
</box>
</geometry>
</collision>
<visual name="linkROV_visual">
<geometry>
<box>
<size>0.4572 0.33805 0.39785</size>
</box>
</geometry>
<material>
<color rgba="0.3 0.3 0.3 1.0"/>
</material>
</visual>
</link>
<link name="arm1link1">
<pose>0.05750000 0.10000000 -0.10000000 -0.19757678 -0.00000000 0.00000000 </pose>
<inertial>
<mass>0.575</mass>
<inertia>
<ixx>3.8333e-05</ixx>
<iyy>6.5286e-04</iyy>
<izz>6.5286e-04</izz>
<ixy>0.0</ixy>
<ixz>0.0</ixz>
<iyz>0.0</iyz>
</inertia>
</inertial>
<collision name="arm1link1_collision">
<geometry>
<box>
<size>0.115 0.02 0.02</size>
</box>
</geometry>
</collision>
<visual name="arm1link1_visual">
<geometry>
<box>
<size>0.115 0.02 0.02</size>
</box>
</geometry>
<material>
<color rgba="0.3 0.3 0.3 1.0"/>
</material>
</visual>
</link>
<link name="arm1link2">
<pose>0.17971619 0.12616081 -0.10523709 -0.18300683 0.07488558 0.38415540 </pose>
<inertial>
<mass>0.700</mass>
<inertia>
<ixx>4.6667e-05</ixx>
<iyy>1.1667e-03</iyy>
<izz>1.1667e-03</izz>
<ixy>0.0</ixy>
<ixz>0.0</ixz>
<iyz>0.0</iyz>
</inertia>
</inertial>
<collision name="arm1link2_collision">
<geometry>
<box>
<size>0.140 0.02 0.02</size>
</box>
</geometry>
</collision>
<visual name="arm1link2_visual">
<geometry>
<box>
<size>0.140 0.02 0.02</size>
</box>
</geometry>
<material>
<color rgba="0.3 0.3 0.3 1.0"/>
</material>
</visual>
</link>
<link name="arm1link3">
<pose>0.26362743 0.20546862 -0.12111360 -0.06672910 0.18610576 1.22420614 </pose>
<inertial>
<mass>0.575</mass>
<inertia>
<ixx>3.8333e-05</ixx>
<iyy>6.5286e-04</iyy>
<izz>6.5286e-04</izz>
<ixy>0.0</ixy>
<ixz>0.0</ixz>
<iyz>0.0</iyz>
</inertia>
</inertial>
<collision name="arm1link3_collision">
<geometry>
<box>
<size>0.115 0.02 0.02</size>
</box>
</geometry>
</collision>
<visual name="arm1link3_visual">
<geometry>
<box>
<size>0.115 0.02 0.02</size>
</box>
</geometry>
<material>
<color rgba="0.3 0.3 0.3 1.0"/>
</material>
</visual>
</link>
<link name="arm1link4">
<pose>0.29951383 0.30483038 -0.14100468 -0.06738213 0.18610576 1.22420614 </pose>
<inertial>
<mass>0.500</mass>
<inertia>
<ixx>3.3333e-05</ixx>
<iyy>4.3333e-04</iyy>
<izz>4.3333e-04</izz>
<ixy>0.0</ixy>
<ixz>0.0</ixz>
<iyz>0.0</iyz>
</inertia>
</inertial>
<collision name="arm1link4_collision">
<geometry>
<box>
<size>0.100 0.02 0.02</size>
</box>
</geometry>
</collision>
<visual name="arm1link4_visual">
<geometry>
<box>
<size>0.100 0.02 0.02</size>
</box>
</geometry>
<material>
<color rgba="0.3 0.3 0.3 1.0"/>
</material>
</visual>
</link>
<link name="arm1link5">
<pose>0.37370516 0.35102592 -0.15021639 -0.19779452 -0.00069485 -0.00033451 </pose>
<inertial>
<mass>0.575</mass>
<inertia>
<ixx>3.8333e-05</ixx>
<iyy>6.5286e-04</iyy>
<izz>6.5286e-04</izz>
<ixy>0.0</ixy>
<ixz>0.0</ixz>
<iyz>0.0</iyz>
</inertia>
</inertial>
<collision name="arm1link5_collision">
<geometry>
<box>
<size>0.115 0.02 0.02</size>
</box>
</geometry>
</collision>
<visual name="arm1link5_visual">
<geometry>
<box>
<size>0.115 0.02 0.02</size>
</box>
</geometry>
<material>
<color rgba="0.3 0.3 0.3 1.0"/>
</material>
</visual>
</link>
<link name="arm1link6">
<pose>0.49120513 0.35098662 -0.15013475 0.00024483 -0.00069485 -0.00033451 </pose>
<inertial>
<mass>0.600</mass>
<inertia>
<ixx>4.0000e-05</ixx>
<iyy>7.4000e-04</iyy>
<izz>7.4000e-04</izz>
<ixy>0.0</ixy>
<ixz>0.0</ixz>
<iyz>0.0</iyz>
</inertia>
</inertial>
<collision name="arm1link6_collision">
<geometry>
<box>
<size>0.120 0.02 0.02</size>
</box>
</geometry>
</collision>
<visual name="arm1link6_visual">
<geometry>
<box>
<size>0.120 0.02 0.02</size>
</box>
</geometry>
<material>
<color rgba="0.3 0.3 0.3 1.0"/>
</material>
</visual>
</link>
<link name="arm2link1">
<pose>0.05750000 -0.10000000 -0.10000000 0.32685000 0.00000000 0.00000000 </pose>
<inertial>
<mass>0.575</mass>
<inertia>
<ixx>3.8333e-05</ixx>
<iyy>6.5286e-04</iyy>
<izz>6.5286e-04</izz>
<ixy>0.0</ixy>
<ixz>0.0</ixz>
<iyz>0.0</iyz>
</inertia>
</inertial>
<collision name="arm2link1_collision">
<geometry>
<box>
<size>0.115 0.02 0.02</size>
</box>
</geometry>
</collision>
<visual name="arm2link1_visual">
<geometry>
<box>
<size>0.115 0.02 0.02</size>
</box>
</geometry>
<material>
<color rgba="0.3 0.3 0.3 1.0"/>
</material>
</visual>
</link>
<link name="arm2link2">
<pose>0.10863000 -0.16602000 -0.12238000 -0.03083700 0.32545000 -1.66700000 </pose>
<inertial>
<mass>0.700</mass>
<inertia>
<ixx>4.6667e-05</ixx>
<iyy>1.1667e-03</iyy>
<izz>1.1667e-03</izz>
<ixy>0.0</ixy>
<ixz>0.0</ixz>
<iyz>0.0</iyz>
</inertia>
</inertial>
<collision name="arm2link2_collision">
<geometry>
<box>
<size>0.140 0.02 0.02</size>
</box>
</geometry>
</collision>
<visual name="arm2link2_visual">
<geometry>
<box>
<size>0.140 0.02 0.02</size>
</box>
</geometry>
<material>
<color rgba="0.3 0.3 0.3 1.0"/>
</material>
</visual>
</link>
<link name="arm2link3">
<pose>0.15954000 -0.23677000 -0.14637000 0.32570000 0.02789200 -0.08239000 </pose>
<inertial>
<mass>0.575</mass>
<inertia>
<ixx>3.8333e-05</ixx>
<iyy>6.5286e-04</iyy>
<izz>6.5286e-04</izz>
<ixy>0.0</ixy>
<ixz>0.0</ixz>
<iyz>0.0</iyz>
</inertia>
</inertial>
<collision name="arm2link3_collision">
<geometry>
<box>
<size>0.115 0.02 0.02</size>
</box>
</geometry>
</collision>
<visual name="arm2link3_visual">
<geometry>
<box>
<size>0.115 0.02 0.02</size>
</box>
</geometry>
<material>
<color rgba="0.3 0.3 0.3 1.0"/>
</material>
</visual>
</link>
<link name="arm2link4">
<pose>0.26664000 -0.24561000 -0.14936000 0.32447000 0.02789200 -0.08239000 </pose>
<inertial>
<mass>0.500</mass>
<inertia>
<ixx>3.3333e-05</ixx>
<iyy>4.3333e-04</iyy>
<izz>4.3333e-04</izz>
<ixy>0.0</ixy>
<ixz>0.0</ixz>
<iyz>0.0</iyz>
</inertia>
</inertial>
<collision name="arm2link4_collision">
<geometry>
<box>
<size>0.100 0.02 0.02</size>
</box>
</geometry>
</collision>
<visual name="arm2link4_visual">
<geometry>
<box>
<size>0.100 0.02 0.02</size>
</box>
</geometry>
<material>
<color rgba="0.3 0.3 0.3 1.0"/>
</material>
</visual>
</link>
<link name="arm2link5">
<pose>0.37395000 -0.24972000 -0.15076000 0.32563000 0.00005702 0.00016539 </pose>
<inertial>
<mass>0.575</mass>
<inertia>
<ixx>3.8333e-05</ixx>
<iyy>6.5286e-04</iyy>
<izz>6.5286e-04</izz>
<ixy>0.0</ixy>
<ixz>0.0</ixz>
<iyz>0.0</iyz>
</inertia>
</inertial>
<collision name="arm2link5_collision">
<geometry>
<box>
<size>0.115 0.02 0.02</size>
</box>
</geometry>
</collision>
<visual name="arm2link5_visual">
<geometry>
<box>
<size>0.115 0.02 0.02</size>
</box>
</geometry>
<material>
<color rgba="0.3 0.3 0.3 1.0"/>
</material>
</visual>
</link>
<link name="arm2link6">
<pose>0.49145000 -0.24970000 -0.15077000 0.00000413 0.00005702 0.00016539 </pose>
<inertial>
<mass>0.600</mass>
<inertia>
<ixx>4.0000e-05</ixx>
<iyy>7.4000e-04</iyy>
<izz>7.4000e-04</izz>
<ixy>0.0</ixy>
<ixz>0.0</ixz>
<iyz>0.0</iyz>
</inertia>
</inertial>
<collision name="arm2link6_collision">
<geometry>
<box>
<size>0.120 0.02 0.02</size>
</box>
</geometry>
</collision>
<visual name="arm2link6_visual">
<geometry>
<box>
<size>0.120 0.02 0.02</size>
</box>
</geometry>
<material>
<color rgba="0.3 0.3 0.3 1.0"/>
</material>
</visual>
</link>
<link name="arm3link1">
<pose>0.05750000 0.00000000 0.14142000 1.33790000 0.00000000 0.00000000 </pose>
<inertial>
<mass>0.575</mass>
<inertia>
<ixx>3.8333e-05</ixx>
<iyy>6.5286e-04</iyy>
<izz>6.5286e-04</izz>
<ixy>0.0</ixy>
<ixz>0.0</ixz>
<iyz>0.0</iyz>
</inertia>
</inertial>
<collision name="arm3link1_collision">
<geometry>
<box>
<size>0.115 0.02 0.02</size>
</box>
</geometry>
</collision>
<visual name="arm3link1_visual">
<geometry>
<box>
<size>0.115 0.02 0.02</size>
</box>
</geometry>
<material>
<color rgba="0.3 0.3 0.3 1.0"/>
</material>
</visual>
</link>
<link name="arm3link2">
<pose>0.18487000 0.00098561 0.14558000 1.33750000 -0.05939700 0.01410600 </pose>
<inertial>
<mass>0.700</mass>
<inertia>
<ixx>4.6667e-05</ixx>
<iyy>1.1667e-03</iyy>
<izz>1.1667e-03</izz>
<ixy>0.0</ixy>
<ixz>0.0</ixz>
<iyz>0.0</iyz>
</inertia>
</inertial>
<collision name="arm3link2_collision">
<geometry>
<box>
<size>0.140 0.02 0.02</size>
</box>
</geometry>
</collision>
<visual name="arm3link2_visual">
<geometry>
<box>
<size>0.140 0.02 0.02</size>
</box>
</geometry>
<material>
<color rgba="0.3 0.3 0.3 1.0"/>
</material>
</visual>
</link>
<link name="arm3link3">
<pose>0.27132000 0.01467800 0.20330000 0.88254000 -1.19890000 0.65379000 </pose>
<inertial>
<mass>0.575</mass>
<inertia>
<ixx>3.8333e-05</ixx>
<iyy>6.5286e-04</iyy>
<izz>6.5286e-04</izz>
<ixy>0.0</ixy>
<ixz>0.0</ixz>
<iyz>0.0</iyz>
</inertia>
</inertial>
<collision name="arm3link3_collision">
<geometry>
<box>
<size>0.115 0.02 0.02</size>
</box>
</geometry>
</collision>
<visual name="arm3link3_visual">
<geometry>
<box>
<size>0.115 0.02 0.02</size>
</box>
</geometry>
<material>
<color rgba="0.3 0.3 0.3 1.0"/>
</material>
</visual>
</link>
<link name="arm3link4">
<pose>0.30233000 0.03843300 0.30346000 0.88245000 -1.19890000 0.65379000 </pose>
<inertial>
<mass>0.500</mass>
<inertia>
<ixx>3.3333e-05</ixx>
<iyy>4.3333e-04</iyy>
<izz>4.3333e-04</izz>
<ixy>0.0</ixy>
<ixz>0.0</ixz>
<iyz>0.0</iyz>
</inertia>
</inertial>
<collision name="arm3link4_collision">
<geometry>
<box>
<size>0.100 0.02 0.02</size>
</box>
</geometry>
</collision>
<visual name="arm3link4_visual">
<geometry>
<box>
<size>0.100 0.02 0.02</size>
</box>
</geometry>
<material>
<color rgba="0.3 0.3 0.3 1.0"/>
</material>
</visual>
</link>
<link name="arm3link5">
<pose>0.37425000 0.04947100 0.35001000 1.33790000 0.00046073 -0.00019058 </pose>
<inertial>
<mass>0.575</mass>
<inertia>
<ixx>3.8333e-05</ixx>
<iyy>6.5286e-04</iyy>
<izz>6.5286e-04</izz>
<ixy>0.0</ixy>
<ixz>0.0</ixz>
<iyz>0.0</iyz>
</inertia>
</inertial>
<collision name="arm3link5_collision">
<geometry>
<box>
<size>0.115 0.02 0.02</size>
</box>
</geometry>
</collision>
<visual name="arm3link5_visual">
<geometry>
<box>
<size>0.115 0.02 0.02</size>
</box>
</geometry>
<material>
<color rgba="0.3 0.3 0.3 1.0"/>
</material>
</visual>
</link>
<link name="arm3link6">
<pose>0.49175000 0.04944900 0.34996000 -0.00015445 0.00046073 -0.00019058 </pose>
<inertial>
<mass>0.600</mass>
<inertia>
<ixx>4.0000e-05</ixx>
<iyy>7.4000e-04</iyy>
<izz>7.4000e-04</izz>
<ixy>0.0</ixy>
<ixz>0.0</ixz>
<iyz>0.0</iyz>
</inertia>
</inertial>
<collision name="arm3link6_collision">
<geometry>
<box>
<size>0.120 0.02 0.02</size>
</box>
</geometry>
</collision>
<visual name="arm3link6_visual">
<geometry>
<box>
<size>0.120 0.02 0.02</size>
</box>
</geometry>
<material>
<color rgba="0.3 0.3 0.3 1.0"/>
</material>
</visual>
</link>
<joint name="arm1_jointgrip" type="fixed">
<pose>0 0 0 0 0 0</pose>
<parent>world</parent>
<child>arm1link6</child>
</joint>
<joint name="arm1_joint1" type="revolute">
<pose>0 0 0 0 0 0</pose>
<parent>linkROV</parent>
<child>arm1link1</child>
<axis>
<xyz>1 0 0</xyz>
<dynamics>
<damping>0.05</damping>
<friction>0</friction>
<spring_reference>0</spring_reference>
<spring_stiffness>10.0</spring_stiffness>
</dynamics>
</axis>
</joint>
<joint name="arm1_joint2" type="revolute">
<pose>-0.07 0 0 0 0 0</pose>
<parent>arm1link1</parent>
<child>arm1link2</child>
<axis>
<xyz>0 0 1</xyz>
<dynamics>
<damping>0.05</damping>
<friction>0</friction>
<spring_reference>0</spring_reference>
<spring_stiffness>10.0</spring_stiffness>
</dynamics>
</axis>
</joint>
<joint name="arm1_joint3" type="revolute">
<pose>-0.0575 0 0 0 0 0</pose>
<parent>arm1link2</parent>
<child>arm1link3</child>
<axis>
<xyz>0 0 1</xyz>
<dynamics>
<damping>0.05</damping>
<friction>0</friction>
<spring_reference>0</spring_reference>
<spring_stiffness>10.0</spring_stiffness>
</dynamics>
</axis>
</joint>
<joint name="arm1_joint4" type="revolute">
<pose>-0.05 0 0 0 0 0</pose>
<parent>arm1link3</parent>
<child>arm1link4</child>
<axis>
<xyz>1 0 0</xyz>
<dynamics>
<damping>0.05</damping>
<friction>0</friction>
<spring_reference>0</spring_reference>
<spring_stiffness>10.0</spring_stiffness>
</dynamics>
</axis>
</joint>
<joint name="arm1_joint5" type="revolute">
<pose>-0.0575 0 0 0 0 0</pose>
<parent>arm1link4</parent>
<child>arm1link5</child>
<axis>
<xyz>0 0 1</xyz>
<dynamics>
<damping>0.05</damping>
<friction>0</friction>
<spring_reference>0</spring_reference>
<spring_stiffness>10.0</spring_stiffness>
</dynamics>
</axis>
</joint>
<joint name="arm1_joint6" type="revolute">
<pose>-0.06 0 0 0 0 0</pose>
<parent>arm1link5</parent>
<child>arm1link6</child>
<axis>
<xyz>1 0 0</xyz>
<dynamics>
<damping>0.05</damping>
<friction>0</friction>
<spring_reference>0</spring_reference>
<spring_stiffness>10.0</spring_stiffness>
</dynamics>
</axis>
</joint>
<joint name="arm2_jointgrip" type="fixed">
<pose>0 0 0 0 0 0</pose>
<parent>world</parent>
<child>arm2link6</child>
</joint>
<joint name="arm2_joint1" type="revolute">
<pose>0 0 0 0 0 0</pose>
<parent>linkROV</parent>
<child>arm2link1</child>
<axis>
<xyz>1 0 0</xyz>
<dynamics>
<damping>0.05</damping>
<friction>0</friction>
<spring_reference>0</spring_reference>
<spring_stiffness>10.0</spring_stiffness>
</dynamics>
</axis>
</joint>
<joint name="arm2_joint2" type="revolute">
<pose>-0.07 0 0 0 0 0</pose>
<parent>arm2link1</parent>
<child>arm2link2</child>
<axis>
<xyz>0 0 1</xyz>
<dynamics>
<damping>0.05</damping>
<friction>0</friction>
<spring_reference>0</spring_reference>
<spring_stiffness>10.0</spring_stiffness>
</dynamics>
</axis>
</joint>
<joint name="arm2_joint3" type="revolute">
<pose>-0.0575 0 0 0 0 0</pose>
<parent>arm2link2</parent>
<child>arm2link3</child>
<axis>
<xyz>0 0 1</xyz>
<dynamics>
<damping>0.05</damping>
<friction>0</friction>
<spring_reference>0</spring_reference>
<spring_stiffness>10.0</spring_stiffness>
</dynamics>
</axis>
</joint>
<joint name="arm2_joint4" type="revolute">
<pose>-0.05 0 0 0 0 0</pose>
<parent>arm2link3</parent>
<child>arm2link4</child>
<axis>
<xyz>1 0 0</xyz>
<dynamics>
<damping>0.05</damping>
<friction>0</friction>
<spring_reference>0</spring_reference>
<spring_stiffness>10.0</spring_stiffness>
</dynamics>
</axis>
</joint>
<joint name="arm2_joint5" type="revolute">
<pose>-0.0575 0 0 0 0 0</pose>
<parent>arm2link4</parent>
<child>arm2link5</child>
<axis>
<xyz>0 0 1</xyz>
<dynamics>
<damping>0.05</damping>
<friction>0</friction>
<spring_reference>0</spring_reference>
<spring_stiffness>10.0</spring_stiffness>
</dynamics>
</axis>
</joint>
<joint name="arm2_joint6" type="revolute">
<pose>-0.06 0 0 0 0 0</pose>
<parent>arm2link5</parent>
<child>arm2link6</child>
<axis>
<xyz>1 0 0</xyz>
<dynamics>
<damping>0.05</damping>
<friction>0</friction>
<spring_reference>0</spring_reference>
<spring_stiffness>10.0</spring_stiffness>
</dynamics>
</axis>
</joint>
<joint name="arm3_jointgrip" type="fixed">
<pose>0 0 0 0 0 0</pose>
<parent>world</parent>
<child>arm3link6</child>
</joint>
<joint name="arm3_joint1" type="revolute">
<pose>0 0 0 0 0 0</pose>
<parent>linkROV</parent>
<child>arm3link1</child>
<axis>
<xyz>1 0 0</xyz>
<dynamics>
<damping>0.05</damping>
<friction>0</friction>
<spring_reference>0</spring_reference>
<spring_stiffness>10.0</spring_stiffness>
</dynamics>
</axis>
</joint>
<joint name="arm3_joint2" type="revolute">
<pose>-0.07 0 0 0 0 0</pose>
<parent>arm3link1</parent>
<child>arm3link2</child>
<axis>
<xyz>0 0 1</xyz>
<dynamics>
<damping>0.05</damping>
<friction>0</friction>
<spring_reference>0</spring_reference>
<spring_stiffness>10.0</spring_stiffness>
</dynamics>
</axis>
</joint>
<joint name="arm3_joint3" type="revolute">
<pose>-0.0575 0 0 0 0 0</pose>
<parent>arm3link2</parent>
<child>arm3link3</child>
<axis>
<xyz>0 0 1</xyz>
<dynamics>
<damping>0.05</damping>
<friction>0</friction>
<spring_reference>0</spring_reference>
<spring_stiffness>10.0</spring_stiffness>
</dynamics>
</axis>
</joint>
<joint name="arm3_joint4" type="revolute">
<pose>-0.05 0 0 0 0 0</pose>
<parent>arm3link3</parent>
<child>arm3link4</child>
<axis>
<xyz>1 0 0</xyz>
<dynamics>
<damping>0.05</damping>
<friction>0</friction>
<spring_reference>0</spring_reference>
<spring_stiffness>10.0</spring_stiffness>
</dynamics>
</axis>
</joint>
<joint name="arm3_joint5" type="revolute">
<pose>-0.0575 0 0 0 0 0</pose>
<parent>arm3link4</parent>
<child>arm3link5</child>
<axis>
<xyz>0 0 1</xyz>
<dynamics>
<damping>0.05</damping>
<friction>0</friction>
<spring_reference>0</spring_reference>
<spring_stiffness>10.0</spring_stiffness>
</dynamics>
</axis>
</joint>
<joint name="arm3_joint6" type="revolute">
<pose>-0.06 0 0 0 0 0</pose>
<parent>arm3link5</parent>
<child>arm3link6</child>
<axis>
<xyz>1 0 0</xyz>
<dynamics>
<damping>0.05</damping>
<friction>0</friction>
<spring_reference>0</spring_reference>
<spring_stiffness>10.0</spring_stiffness>
</dynamics>
</axis>
</joint>
</model>
</sdf>
