<?xml version="1.0" ?>
<sdf version="1.5">
  <model name="four_bar_sdf">
    <!-- <pose>0 0 0.04  0 0 0</pose> -->
    <pose>0 0 0 0 0 0</pose>
    <self_collide>true</self_collide>
    <link name="linkROV">
      <pose>-0.2286 0 0 0 0 0</pose>
<!--       <inertial>
        <mass>76.8629</mass>
        <inertia>
          <ixx>1.7458</ixx>
          <iyy>2.3527</iyy>
          <izz>2.0709</izz>
          <ixy>0.0</ixy>
          <ixz>0.0</ixz>
          <iyz>0.0</iyz>
        </inertia>
      </inertial> -->
      <inertial>
        <mass>1.0</mass>
        <inertia>
          <ixx>0.0227</ixx>
          <iyy>0.0306</iyy>
          <izz>0.0269</izz>
          <ixy>0.0</ixy>
          <ixz>0.0</ixz>
          <iyz>0.0</iyz>
        </inertia>
      </inertial>
      <collision name="linkROV_collision">
        <geometry>
          <box>
            <size>0.4572 0.33805 0.39785</size>
          </box>
        </geometry>
      </collision>
      <visual name="linkROV_visual">
        <geometry>
          <box>
            <size>0.4572 0.33805 0.39785</size>
          </box>
        </geometry>
        <material>
          <color rgba="0.3 0.3 0.3 1.0"/>
        </material>
      </visual>
    </link>
    <link name="arm1link1">
      <pose>0.0575 0.1 -0.1 -0.5236 0 0 </pose>
      <inertial>
        <mass>0.575</mass>
        <inertia>
          <ixx>3.8333e-05</ixx>
          <iyy>6.5286e-04</iyy>
          <izz>6.5286e-04</izz>
          <ixy>0.0</ixy>
          <ixz>0.0</ixz>
          <iyz>0.0</iyz>
        </inertia>
      </inertial>
      <collision name="arm1link1_collision">
        <geometry>
          <box>
            <size>0.115 0.02 0.02</size>
          </box>
        </geometry>
      </collision>
      <visual name="arm1link1_visual">
        <geometry>
          <box>
            <size>0.115 0.02 0.02</size>
          </box>
        </geometry>
        <material>
          <color rgba="0.3 0.3 0.3 1.0"/>
        </material>
      </visual>
    </link>
    <link name="arm1link2">
      <pose>0.15 0.1525 -0.13031 -0.28103 0.44783 0.98279 </pose>
      <inertial>
        <mass>0.700</mass>
        <inertia>
          <ixx>4.6667e-05</ixx>
          <iyy>1.1667e-03</iyy>
          <izz>1.1667e-03</izz>
          <ixy>0.0</ixy>
          <ixz>0.0</ixz>
          <iyz>0.0</iyz>
        </inertia>
      </inertial>
      <collision name="arm1link2_collision">
        <geometry>
          <box>
            <size>0.140 0.02 0.02</size>
          </box>
        </geometry>
      </collision>
      <visual name="arm1link2_visual">
        <geometry>
          <box>
            <size>0.140 0.02 0.02</size>
          </box>
        </geometry>
        <material>
          <color rgba="0.3 0.3 0.3 1.0"/>
        </material>
      </visual>
    </link>
    <link name="arm1link3">
      <pose>0.2348 0.2299 -0.175 -0.46365 0.25268 0.46365 </pose>
      <inertial>
        <mass>0.575</mass>
        <inertia>
          <ixx>3.8333e-05</ixx>
          <iyy>6.5286e-04</iyy>
          <izz>6.5286e-04</izz>
          <ixy>0.0</ixy>
          <ixz>0.0</ixz>
          <iyz>0.0</iyz>
        </inertia>
      </inertial>
      <collision name="arm1link3_collision">
        <geometry>
          <box>
            <size>0.115 0.02 0.02</size>
          </box>
        </geometry>
      </collision>
      <visual name="arm1link3_visual">
        <geometry>
          <box>
            <size>0.115 0.02 0.02</size>
          </box>
        </geometry>
        <material>
          <color rgba="0.3 0.3 0.3 1.0"/>
        </material>
      </visual>
    </link>
    <link name="arm1link4">
      <pose>0.32789 0.27645 -0.20187 -0.46365 0.25268 0.46365 </pose>
      <inertial>
        <mass>0.500</mass>
        <inertia>
          <ixx>3.3333e-05</ixx>
          <iyy>4.3333e-04</iyy>
          <izz>4.3333e-04</izz>
          <ixy>0.0</ixy>
          <ixz>0.0</ixz>
          <iyz>0.0</iyz>
        </inertia>
      </inertial>
      <collision name="arm1link4_collision">
        <geometry>
          <box>
            <size>0.100 0.02 0.02</size>
          </box>
        </geometry>
      </collision>
      <visual name="arm1link4_visual">
        <geometry>
          <box>
            <size>0.100 0.02 0.02</size>
          </box>
        </geometry>
        <material>
          <color rgba="0.3 0.3 0.3 1.0"/>
        </material>
      </visual>
    </link>
    <link name="arm1link5">
      <pose>0.4287 0.2981 -0.21437 -0.5236 0 0 </pose>
      <inertial>
        <mass>0.575</mass>
        <inertia>
          <ixx>3.8333e-05</ixx>
          <iyy>6.5286e-04</iyy>
          <izz>6.5286e-04</izz>
          <ixy>0.0</ixy>
          <ixz>0.0</ixz>
          <iyz>0.0</iyz>
        </inertia>
      </inertial>
      <collision name="arm1link5_collision">
        <geometry>
          <box>
            <size>0.115 0.02 0.02</size>
          </box>
        </geometry>
      </collision>
      <visual name="arm1link5_visual">
        <geometry>
          <box>
            <size>0.115 0.02 0.02</size>
          </box>
        </geometry>
        <material>
          <color rgba="0.3 0.3 0.3 1.0"/>
        </material>
      </visual>
    </link>
    <link name="arm1link6">
      <pose>0.5462 0.2981 -0.21437 0 0 0 </pose>
      <inertial>
        <mass>0.600</mass>
        <inertia>
          <ixx>4.0000e-05</ixx>
          <iyy>7.4000e-04</iyy>
          <izz>7.4000e-04</izz>
          <ixy>0.0</ixy>
          <ixz>0.0</ixz>
          <iyz>0.0</iyz>
        </inertia>
      </inertial>
      <collision name="arm1link6_collision">
        <geometry>
          <box>
            <size>0.120 0.02 0.02</size>
          </box>
        </geometry>
      </collision>
      <visual name="arm1link6_visual">
        <geometry>
          <box>
            <size>0.120 0.02 0.02</size>
          </box>
        </geometry>
        <material>
          <color rgba="0.3 0.3 0.3 1.0"/>
        </material>
      </visual>
    </link>






    <link name="arm2link1">
      <pose>0.0575 -0.1 -0.1 0.5236 0 0 </pose>
      <inertial>
        <mass>0.575</mass>
        <inertia>
          <ixx>3.8333e-05</ixx>
          <iyy>6.5286e-04</iyy>
          <izz>6.5286e-04</izz>
          <ixy>0.0</ixy>
          <ixz>0.0</ixz>
          <iyz>0.0</iyz>
        </inertia>
      </inertial>
      <collision name="arm2link1_collision">
        <geometry>
          <box>
            <size>0.115 0.02 0.02</size>
          </box>
        </geometry>
      </collision>
      <visual name="arm2link1_visual">
        <geometry>
          <box>
            <size>0.115 0.02 0.02</size>
          </box>
        </geometry>
        <material>
          <color rgba="0.3 0.3 0.3 1.0"/>
        </material>
      </visual>
    </link>
    <link name="arm2link2">
      <pose>0.15 -0.1525 -0.13031 0.28103 0.44783 -0.98279 </pose>
      <inertial>
        <mass>0.700</mass>
        <inertia>
          <ixx>4.6667e-05</ixx>
          <iyy>1.1667e-03</iyy>
          <izz>1.1667e-03</izz>
          <ixy>0.0</ixy>
          <ixz>0.0</ixz>
          <iyz>0.0</iyz>
        </inertia>
      </inertial>
      <collision name="arm2link2_collision">
        <geometry>
          <box>
            <size>0.140 0.02 0.02</size>
          </box>
        </geometry>
      </collision>
      <visual name="arm2link2_visual">
        <geometry>
          <box>
            <size>0.140 0.02 0.02</size>
          </box>
        </geometry>
        <material>
          <color rgba="0.3 0.3 0.3 1.0"/>
        </material>
      </visual>
    </link>
    <link name="arm2link3">
      <pose>0.2348 -0.2299 -0.175 0.46365 0.25268 -0.46365 </pose>
      <inertial>
        <mass>0.575</mass>
        <inertia>
          <ixx>3.8333e-05</ixx>
          <iyy>6.5286e-04</iyy>
          <izz>6.5286e-04</izz>
          <ixy>0.0</ixy>
          <ixz>0.0</ixz>
          <iyz>0.0</iyz>
        </inertia>
      </inertial>
      <collision name="arm2link3_collision">
        <geometry>
          <box>
            <size>0.115 0.02 0.02</size>
          </box>
        </geometry>
      </collision>
      <visual name="arm2link3_visual">
        <geometry>
          <box>
            <size>0.115 0.02 0.02</size>
          </box>
        </geometry>
        <material>
          <color rgba="0.3 0.3 0.3 1.0"/>
        </material>
      </visual>
    </link>
    <link name="arm2link4">
      <pose>0.32789 -0.27645 -0.20187 0.46365 0.25268 -0.46365 </pose>
      <inertial>
        <mass>0.500</mass>
        <inertia>
          <ixx>3.3333e-05</ixx>
          <iyy>4.3333e-04</iyy>
          <izz>4.3333e-04</izz>
          <ixy>0.0</ixy>
          <ixz>0.0</ixz>
          <iyz>0.0</iyz>
        </inertia>
      </inertial>
      <collision name="arm2link4_collision">
        <geometry>
          <box>
            <size>0.100 0.02 0.02</size>
          </box>
        </geometry>
      </collision>
      <visual name="arm2link4_visual">
        <geometry>
          <box>
            <size>0.100 0.02 0.02</size>
          </box>
        </geometry>
        <material>
          <color rgba="0.3 0.3 0.3 1.0"/>
        </material>
      </visual>
    </link>
    <link name="arm2link5">
      <pose>0.4287 -0.2981 -0.21437 0.5236 0 0 </pose>
      <inertial>
        <mass>0.575</mass>
        <inertia>
          <ixx>3.8333e-05</ixx>
          <iyy>6.5286e-04</iyy>
          <izz>6.5286e-04</izz>
          <ixy>0.0</ixy>
          <ixz>0.0</ixz>
          <iyz>0.0</iyz>
        </inertia>
      </inertial>
      <collision name="arm2link5_collision">
        <geometry>
          <box>
            <size>0.115 0.02 0.02</size>
          </box>
        </geometry>
      </collision>
      <visual name="arm2link5_visual">
        <geometry>
          <box>
            <size>0.115 0.02 0.02</size>
          </box>
        </geometry>
        <material>
          <color rgba="0.3 0.3 0.3 1.0"/>
        </material>
      </visual>
    </link>
    <link name="arm2link6">
      <pose>0.5462 -0.2981 -0.21437 0 0 0 </pose>
      <inertial>
        <mass>0.600</mass>
        <inertia>
          <ixx>4.0000e-05</ixx>
          <iyy>7.4000e-04</iyy>
          <izz>7.4000e-04</izz>
          <ixy>0.0</ixy>
          <ixz>0.0</ixz>
          <iyz>0.0</iyz>
        </inertia>
      </inertial>
      <collision name="arm2link6_collision">
        <geometry>
          <box>
            <size>0.120 0.02 0.02</size>
          </box>
        </geometry>
      </collision>
      <visual name="arm2link6_visual">
        <geometry>
          <box>
            <size>0.120 0.02 0.02</size>
          </box>
        </geometry>
        <material>
          <color rgba="0.3 0.3 0.3 1.0"/>
        </material>
      </visual>
    </link>






    <link name="arm3link1">
      <pose>0.0575 0 0.14142 1.5708 0 0 </pose>
      <inertial>
        <mass>0.575</mass>
        <inertia>
          <ixx>3.8333e-05</ixx>
          <iyy>6.5286e-04</iyy>
          <izz>6.5286e-04</izz>
          <ixy>0.0</ixy>
          <ixz>0.0</ixz>
          <iyz>0.0</iyz>
        </inertia>
      </inertial>
      <collision name="arm3link1_collision">
        <geometry>
          <box>
            <size>0.115 0.02 0.02</size>
          </box>
        </geometry>
      </collision>
      <visual name="arm3link1_visual">
        <geometry>
          <box>
            <size>0.115 0.02 0.02</size>
          </box>
        </geometry>
        <material>
          <color rgba="0.3 0.3 0.3 1.0"/>
        </material>
      </visual>
    </link>
    <link name="arm3link2">
      <pose>0.15 3.712e-18 0.20204 1.5708 -1.0472 1.0606e-16 </pose>
      <inertial>
        <mass>0.700</mass>
        <inertia>
          <ixx>4.6667e-05</ixx>
          <iyy>1.1667e-03</iyy>
          <izz>1.1667e-03</izz>
          <ixy>0.0</ixy>
          <ixz>0.0</ixz>
          <iyz>0.0</iyz>
        </inertia>
      </inertial>
      <collision name="arm3link2_collision">
        <geometry>
          <box>
            <size>0.140 0.02 0.02</size>
          </box>
        </geometry>
      </collision>
      <visual name="arm3link2_visual">
        <geometry>
          <box>
            <size>0.140 0.02 0.02</size>
          </box>
        </geometry>
        <material>
          <color rgba="0.3 0.3 0.3 1.0"/>
        </material>
      </visual>
    </link>
    <link name="arm3link3">
      <pose>0.2348 9.1845e-18 0.29141 1.5708 -0.5236 3.5353e-17 </pose>
      <inertial>
        <mass>0.575</mass>
        <inertia>
          <ixx>3.8333e-05</ixx>
          <iyy>6.5286e-04</iyy>
          <izz>6.5286e-04</izz>
          <ixy>0.0</ixy>
          <ixz>0.0</ixz>
          <iyz>0.0</iyz>
        </inertia>
      </inertial>
      <collision name="arm3link3_collision">
        <geometry>
          <box>
            <size>0.115 0.02 0.02</size>
          </box>
        </geometry>
      </collision>
      <visual name="arm3link3_visual">
        <geometry>
          <box>
            <size>0.115 0.02 0.02</size>
          </box>
        </geometry>
        <material>
          <color rgba="0.3 0.3 0.3 1.0"/>
        </material>
      </visual>
    </link>
    <link name="arm3link4">
      <pose>0.32789 1.2476e-17 0.34516 1.5708 -0.5236 3.5353e-17 </pose>
      <inertial>
        <mass>0.500</mass>
        <inertia>
          <ixx>3.3333e-05</ixx>
          <iyy>4.3333e-04</iyy>
          <izz>4.3333e-04</izz>
          <ixy>0.0</ixy>
          <ixz>0.0</ixz>
          <iyz>0.0</iyz>
        </inertia>
      </inertial>
      <collision name="arm3link4_collision">
        <geometry>
          <box>
            <size>0.100 0.02 0.02</size>
          </box>
        </geometry>
      </collision>
      <visual name="arm3link4_visual">
        <geometry>
          <box>
            <size>0.100 0.02 0.02</size>
          </box>
        </geometry>
        <material>
          <color rgba="0.3 0.3 0.3 1.0"/>
        </material>
      </visual>
    </link>
    <link name="arm3link5">
      <pose>0.4287 1.4007e-17 0.37016 1.5708 -5.5511e-17 0 </pose>
      <inertial>
        <mass>0.575</mass>
        <inertia>
          <ixx>3.8333e-05</ixx>
          <iyy>6.5286e-04</iyy>
          <izz>6.5286e-04</izz>
          <ixy>0.0</ixy>
          <ixz>0.0</ixz>
          <iyz>0.0</iyz>
        </inertia>
      </inertial>
      <collision name="arm3link5_collision">
        <geometry>
          <box>
            <size>0.115 0.02 0.02</size>
          </box>
        </geometry>
      </collision>
      <visual name="arm3link5_visual">
        <geometry>
          <box>
            <size>0.115 0.02 0.02</size>
          </box>
        </geometry>
        <material>
          <color rgba="0.3 0.3 0.3 1.0"/>
        </material>
      </visual>
    </link>
    <link name="arm3link6">
      <pose>0.5462 1.4007e-17 0.37016 0 -5.5511e-17 0 </pose>
      <inertial>
        <mass>0.600</mass>
        <inertia>
          <ixx>4.0000e-05</ixx>
          <iyy>7.4000e-04</iyy>
          <izz>7.4000e-04</izz>
          <ixy>0.0</ixy>
          <ixz>0.0</ixz>
          <iyz>0.0</iyz>
        </inertia>
      </inertial>
      <collision name="arm3link6_collision">
        <geometry>
          <box>
            <size>0.120 0.02 0.02</size>
          </box>
        </geometry>
      </collision>
      <visual name="arm3link6_visual">
        <geometry>
          <box>
            <size>0.120 0.02 0.02</size>
          </box>
        </geometry>
        <material>
          <color rgba="0.3 0.3 0.3 1.0"/>
        </material>
      </visual>
    </link>



<!--     <joint name="jointbase" type="fixed">
      <pose>-0.0575 0 0 0 0 0</pose>
      <parent>world</parent>
      <child>linkROV</child>
    </joint> -->
    <joint name="arm1_jointgrip" type="fixed">
      <pose>0 0 0 0 0 0</pose>
      <parent>world</parent>
      <child>arm1link6</child>
    </joint>
    <joint name="arm1_joint1" type="revolute">
      <pose>0 0 0 0 0 0</pose>
      <parent>linkROV</parent>
      <child>arm1link1</child>
      <axis>
        <xyz>1 0 0</xyz>
        <dynamics>
          <damping>0.05</damping>
          <friction>0</friction>
          <spring_reference>0</spring_reference>
          <spring_stiffness>10.0</spring_stiffness>
        </dynamics>
      </axis>
    </joint>
    <joint name="arm1_joint2" type="revolute">
      <pose>-0.07 0 0 0 0 0</pose>
      <parent>arm1link1</parent>
      <child>arm1link2</child>
      <axis>
        <xyz>0 0 1</xyz>
        <dynamics>
          <damping>0.05</damping>
          <friction>0</friction>
          <spring_reference>0</spring_reference>
          <spring_stiffness>10.0</spring_stiffness>
        </dynamics>
      </axis>
    </joint>
    <joint name="arm1_joint3" type="revolute">
      <pose>-0.0575 0 0 0 0 0</pose>
      <parent>arm1link2</parent>
      <child>arm1link3</child>
      <axis>
        <xyz>0 0 1</xyz>
        <dynamics>
          <damping>0.05</damping>
          <friction>0</friction>
          <spring_reference>0</spring_reference>
          <spring_stiffness>10.0</spring_stiffness>
        </dynamics>
      </axis>
    </joint>
    <joint name="arm1_joint4" type="revolute">
      <pose>-0.05 0 0 0 0 0</pose>
      <parent>arm1link3</parent>
      <child>arm1link4</child>
      <axis>
        <xyz>1 0 0</xyz>
        <dynamics>
          <damping>0.05</damping>
          <friction>0</friction>
          <spring_reference>0</spring_reference>
          <spring_stiffness>10.0</spring_stiffness>
        </dynamics>
      </axis>
    </joint>
    <joint name="arm1_joint5" type="revolute">
      <pose>-0.0575 0 0 0 0 0</pose>
      <parent>arm1link4</parent>
      <child>arm1link5</child>
      <axis>
        <xyz>0 0 1</xyz>
        <dynamics>
          <damping>0.05</damping>
          <friction>0</friction>
          <spring_reference>0</spring_reference>
          <spring_stiffness>10.0</spring_stiffness>
        </dynamics>
      </axis>
    </joint>
    <joint name="arm1_joint6" type="revolute">
      <pose>-0.06 0 0 0 0 0</pose>
      <parent>arm1link5</parent>
      <child>arm1link6</child>
      <axis>
        <xyz>1 0 0</xyz>
        <dynamics>
          <damping>0.05</damping>
          <friction>0</friction>
          <spring_reference>0</spring_reference>
          <spring_stiffness>10.0</spring_stiffness>
        </dynamics>
      </axis>
    </joint>







    <joint name="arm2_jointgrip" type="fixed">
      <pose>0 0 0 0 0 0</pose>
      <parent>world</parent>
      <child>arm2link6</child>
    </joint>
    <joint name="arm2_joint1" type="revolute">
      <pose>0 0 0 0 0 0</pose>
      <parent>linkROV</parent>
      <child>arm2link1</child>
      <axis>
        <xyz>1 0 0</xyz>
        <dynamics>
          <damping>0.05</damping>
          <friction>0</friction>
          <spring_reference>0</spring_reference>
          <spring_stiffness>10.0</spring_stiffness>
        </dynamics>
      </axis>
    </joint>
    <joint name="arm2_joint2" type="revolute">
      <pose>-0.07 0 0 0 0 0</pose>
      <parent>arm2link1</parent>
      <child>arm2link2</child>
      <axis>
        <xyz>0 0 1</xyz>
        <dynamics>
          <damping>0.05</damping>
          <friction>0</friction>
          <spring_reference>0</spring_reference>
          <spring_stiffness>10.0</spring_stiffness>
        </dynamics>
      </axis>
    </joint>
    <joint name="arm2_joint3" type="revolute">
      <pose>-0.0575 0 0 0 0 0</pose>
      <parent>arm2link2</parent>
      <child>arm2link3</child>
      <axis>
        <xyz>0 0 1</xyz>
        <dynamics>
          <damping>0.05</damping>
          <friction>0</friction>
          <spring_reference>0</spring_reference>
          <spring_stiffness>10.0</spring_stiffness>
        </dynamics>
      </axis>
    </joint>
    <joint name="arm2_joint4" type="revolute">
      <pose>-0.05 0 0 0 0 0</pose>
      <parent>arm2link3</parent>
      <child>arm2link4</child>
      <axis>
        <xyz>1 0 0</xyz>
        <dynamics>
          <damping>0.05</damping>
          <friction>0</friction>
          <spring_reference>0</spring_reference>
          <spring_stiffness>10.0</spring_stiffness>
        </dynamics>
      </axis>
    </joint>
    <joint name="arm2_joint5" type="revolute">
      <pose>-0.0575 0 0 0 0 0</pose>
      <parent>arm2link4</parent>
      <child>arm2link5</child>
      <axis>
        <xyz>0 0 1</xyz>
        <dynamics>
          <damping>0.05</damping>
          <friction>0</friction>
          <spring_reference>0</spring_reference>
          <spring_stiffness>10.0</spring_stiffness>
        </dynamics>
      </axis>
    </joint>
    <joint name="arm2_joint6" type="revolute">
      <pose>-0.06 0 0 0 0 0</pose>
      <parent>arm2link5</parent>
      <child>arm2link6</child>
      <axis>
        <xyz>1 0 0</xyz>
        <dynamics>
          <damping>0.05</damping>
          <friction>0</friction>
          <spring_reference>0</spring_reference>
          <spring_stiffness>10.0</spring_stiffness>
        </dynamics>
      </axis>
    </joint>






    <joint name="arm3_jointgrip" type="fixed">
      <pose>0 0 0 0 0 0</pose>
      <parent>world</parent>
      <child>arm3link6</child>
    </joint>
    <joint name="arm3_joint1" type="revolute">
      <pose>0 0 0 0 0 0</pose>
      <parent>linkROV</parent>
      <child>arm3link1</child>
      <axis>
        <xyz>1 0 0</xyz>
        <dynamics>
          <damping>0.05</damping>
          <friction>0</friction>
          <spring_reference>0</spring_reference>
          <spring_stiffness>10.0</spring_stiffness>
        </dynamics>
      </axis>
    </joint>
    <joint name="arm3_joint2" type="revolute">
      <pose>-0.07 0 0 0 0 0</pose>
      <parent>arm3link1</parent>
      <child>arm3link2</child>
      <axis>
        <xyz>0 0 1</xyz>
        <dynamics>
          <damping>0.05</damping>
          <friction>0</friction>
          <spring_reference>0</spring_reference>
          <spring_stiffness>10.0</spring_stiffness>
        </dynamics>
      </axis>
    </joint>
    <joint name="arm3_joint3" type="revolute">
      <pose>-0.0575 0 0 0 0 0</pose>
      <parent>arm3link2</parent>
      <child>arm3link3</child>
      <axis>
        <xyz>0 0 1</xyz>
        <dynamics>
          <damping>0.05</damping>
          <friction>0</friction>
          <spring_reference>0</spring_reference>
          <spring_stiffness>10.0</spring_stiffness>
        </dynamics>
      </axis>
    </joint>
    <joint name="arm3_joint4" type="revolute">
      <pose>-0.05 0 0 0 0 0</pose>
      <parent>arm3link3</parent>
      <child>arm3link4</child>
      <axis>
        <xyz>1 0 0</xyz>
        <dynamics>
          <damping>0.05</damping>
          <friction>0</friction>
          <spring_reference>0</spring_reference>
          <spring_stiffness>10.0</spring_stiffness>
        </dynamics>
      </axis>
    </joint>
    <joint name="arm3_joint5" type="revolute">
      <pose>-0.0575 0 0 0 0 0</pose>
      <parent>arm3link4</parent>
      <child>arm3link5</child>
      <axis>
        <xyz>0 0 1</xyz>
        <dynamics>
          <damping>0.05</damping>
          <friction>0</friction>
          <spring_reference>0</spring_reference>
          <spring_stiffness>10.0</spring_stiffness>
        </dynamics>
      </axis>
    </joint>
    <joint name="arm3_joint6" type="revolute">
      <pose>-0.06 0 0 0 0 0</pose>
      <parent>arm3link5</parent>
      <child>arm3link6</child>
      <axis>
        <xyz>1 0 0</xyz>
        <dynamics>
          <damping>0.05</damping>
          <friction>0</friction>
          <spring_reference>0</spring_reference>
          <spring_stiffness>10.0</spring_stiffness>
        </dynamics>
      </axis>
    </joint>
  </model>
</sdf>